File: samples/VAMASvms.vms
VAMAS Surface Chemical Analysis Standard Data Transfer Format 1988 May 4
Specs
EA125 HSA3500 EA 125[HWType 30:15] MCD-9
Administrator
?
1
Created by SpecsLab2, Version 2.77-r27212
NORM
REGULAR
10
4
Cycle
d
zValue
d
Step
d
Timestamp [ms]
d
0
0
0
0
10
overview
ZnO_0B_XPS
2011
11
25
8
48
19
0
8
File = Z:\ZnO_0B_20111123.xml
Group = ZnO_0B_XPS
First of group = 1
Analyzer lens = High:1.5kV
Analyzer slit = 1:6x12\1:6x12
Scan mode = FixedAnalyzerTransmission
Kinetic energy start = 153.6
Kinetic energy base = 0
XPS
1
0
0
0
Mg
1253.6
0.000000
0
0
45.000000
0
FAT
30
1
4.5432
0
0
0
0
0
overview

-1
kinetic energy
eV
153.6
1
2
counts
d
Transmission
d
pulse counting
0.1
0
0
0
576
4.64006
10618
10804
10530
10409
10529
10548
10479
10279
10253
10296
10297
10125
10014
9947
9928
9831
9780
9934
9821
9601
9657
9613
9565
9476
9359
9457
9542
9607
9343
9308
9171
9239
9081
9098
9097
8940
9040
8976
8981
9021
8891
8720
8745
8725
8703
8556
8872
8817
8804
8690
8680
8610
8528
8669
8650
8552
8539
8481
8415
8565
8618
8488
8572
8431
8492
8351
8580
8483
8451
8350
8349
8468
8617
8366
8445
8262
8604
8563
8398
8389
8267
8486
8492
8558
8573
8485
8778
8722
8517
8600
8732
8686
8761
8644
8649
8715
8799
8668
8957
9081
8979
9302
9287
9364
9535
9528
9403
9439
9213
9119
9056
8868
8508
8429
8314
8106
7863
7717
7517
7609
7364
7520
7261
7081
7345
7189
7234
7016
7155
7057
7034
7106
7007
7055
7073
7045
7235
7004
7139
7076
6971
7062
7088
7275
6956
7069
7001
7093
7005
7038
6977
6984
6968
7074
7085
7097
7006
7027
7084
6846
6920
6986
6977
7057
6943
6964
6997
6816
6860
6920
6911
6956
7022
6846
7004
6865
6894
7056
7021
6943
6845
6971
6983
6925
6849
6918
6991
7016
6887
6919
7023
6968
6789
6787
6932
7150
6931
6968
6798
6966
6907
6833
6987
6944
6809
6927
6727
6946
7030
7059
6841
6996
7069
6869
7049
6846
7019
6898
6937
6861
6982
6932
7065
6973
7037
7001
6906
6941
6949
6837
7125
7036
6945
6835
6899
6898
6849
6906
6848
6767
6879
6892
6883
7020
6897
6965
6983
6830
6897
6990
6983
6857
6961
6964
6925
6998
6961
6912
6868
7022
7090
7075
7174
6942
6936
7055
6996
7187
7098
7199
7274
7121
7318
7190
7083
7206
7208
7242
7072
7180
7368
7276
7165
7331
7374
7385
7386
7306
7298
7228
7376
7441
7403
7540
7511
7632
7625
7581
7574
7818
7637
7561
7737
7859
7942
7801
8067
7820
8149
8043
8086
8362
8268
8427
8538
8835
8836
8734
8594
8592
8337
8464
8464
8576
8562
8825
9117
9287
9315
9800
9692
10136
10156
10183
9699
9623
9398
9325
9281
9052
8980
8967
8654
9135
9035
9114
9093
9391
10219
10849
11648
12080
13108
13942
13516
12527
11054
10094
9499
8799
8439
7855
7689
7095
6589
6343
6177
6077
6129
5989
5894
5994
6038
5825
5914
5855
5883
5854
5780
5941
5721
5833
5755
5741
5861
5835
5733
5732
5901
5965
5849
5801
5822
5827
5771
5773
5846
5915
5757
5910
5901
5739
5604
5903
5836
5816
5751
5899
5737
5928
5883
5894
5955
5770
5716
5891
5863
5811
5725
5720
5866
5896
5796
5866
5881
5826
5772
5730
5809
5831
5869
5777
5860
5862
5812
5874
5795
5986
5945
5788
5962
5855
5985
5870
5960
5786
5689
6068
5784
5841
5955
5848
6003
5968
6003
5862
5754
6091
5862
5963
5928
5983
5994
5934
5989
5913
5946
5960
6014
6060
6032
6035
6003
6042
6081
6087
6220
6098
5976
6016
5781
6067
6054
6013
6092
6125
5945
6104
6142
6148
6108
6080
6207
6113
6243
6127
6131
6368
6352
6293
6192
6151
6313
6141
6302
6219
6248
6321
6328
6247
6444
6224
6447
6452
6446
6436
6565
6620
6340
6455
6505
6497
6408
6730
6458
6663
6600
6583
6452
6637
6608
6535
6713
6610
6618
6776
6870
6885
7036
7199
7090
7192
7252
7265
7568
7282
7181
7015
7046
6908
6749
6660
6609
6662
6426
6436
6309
6220
6057
5858
5871
5906
5889
6089
6751
10756
24632
25837
11787
6670
6170
5853
5701
5686
6492
7458
7032
6562
5782
5406
5353
5356
5346
5392
5457
5335
5322
5357
5324
5233
5350
5245
5176
5285
5175
5200
5271
5366
5377
5138
5207
5155
5120
5268
5141
5208
5241
5248
5313
5319
5268
5346
5222
5374
5322
5412
5365
5148
5250
5280
5387
5135
5261
5182
5303
5290
5195
5252
5131
5270
5179
5175
5157
5216
5149
5267
5318
5146
5210
5220
5297
5076
5230
5263
5228
5172
5208
5064
5220
5107
5308
5344
5224
5221
5213
5231
5274
5238
5220
5249
5224
5270
5217
5220
5207
5197
5235
5304
5201
5231
5200
5308
5333
5359
5412
5362
5284
5389
5300
5292
5185
5328
5272
5251
5249
5186
5385
5386
5207
5268
5270
5177
5363
5343
5141
5255
5312
5437
5428
5461
5470
5388
5232
5155
5308
5262
5193
5278
5396
5404
5204
5260
5273
5295
5398
5348
5152
5285
5171
5339
5329
5274
5191
5210
5210
5219
5342
5380
5301
5330
5304
5358
5346
5355
5488
5172
5202
5414
5312
5427
5373
5308
5325
5422
5282
5353
5446
5434
5331
5416
5426
5498
5390
5419
5445
5288
5390
5581
5448
5445
5449
5466
5487
5505
5504
5367
5455
5515
5504
5410
5440
5346
5544
5511
5534
5519
5550
5560
5447
5706
5536
5645
5562
5548
5490
5589
5455
5701
5770
5504
5604
5594
5581
5673
5694
5658
5685
5649
5747
5737
5861
5664
5604
5544
5543
5405
5491
5504
5427
5625
5654
5977
6496
7732
9306
7102
5786
5527
5523
5499
5557
5508
5753
5818
5649
5596
5403
5430
5472
5481
5548
5620
5690
5621
5436
5695
5493
5587
5471
5691
5651
5652
5508
5683
5620
5625
5653
5634
5649
5756
5771
5735
5596
5642
5714
5893
5803
5948
5743
5798
5798
5787
5908
5843
5767
5703
5860
6015
5753
6014
5816
5998
5943
6007
5862
5913
5920
5902
6035
5940
6175
6011
6079
5931
5969
6052
6071
5983
6005
6198
6215
6287
6300
6272
6316
6419
6549
6414
6414
6440
6258
6378
6152
6206
6301
6350
6363
6423
6494
6604
6461
6712
6779
6836
6850
6752
6799
6625
6504
6412
6358
6151
6316
6296
6290
6439
6494
6648
7010
7301
7786
8057
7646
7406
6522
6277
5843
5648
5545
5604
5487
5414
5529
5670
6484
7136
7125
7811
12661
13834
7114
5243
4919
4667
4641
4476
4680
5156
4880
4750
4279
4320
4344
4435
4634
4666
4536
4406
4219
3971
3934
3659
3772
3748
3680
3669
3753
3817
3898
4218
4529
5105
5636
5392
4824
3929
3396
2980
2797
2666
2594
2655
2689
2442
2490
3440
4546
3663
3252
8854
16469
3839
1657
1343
1544
1436
1392
1454
2273
2020
1779
1247
1069
996
1034
981
992
1072
977
1000
1019
1016
954
927
910
987
1018
928
916
932
916
942
947
954
913
922
962
931
916
881
896
927
960
968
993
965
982
980
1023
992
928
913
894
902
881
882
921
958
890
903
882
876
904
869
844
860
891
825
883
906
1013
1055
1121
1191
1281
1229
1015
929
886
880
858
875
906
934
871
863
889
942
991
957
941
1020
996
924
891
886
885
854
731
658
642
620
612
651
576
635
4.64006
Zn2p
ZnO_0B_XPS
2011
11
25
8
52
9
0
8
File = Z:\ZnO_0B_20111123.xml
Group = ZnO_0B_XPS
First of group = 0
Analyzer lens = High:1.5kV
Analyzer slit = 1:6x12\1:6x12
Scan mode = FixedAnalyzerTransmission
Kinetic energy start = 193.6
Kinetic energy base = 0
XPS
1
0
0
0
Mg
1253.6
0.000000
0
0
45.000000
0
FAT
20
1
4.5432
0
0
0
0
0
Zn2p

-1
kinetic energy
eV
193.6
0.1
2
counts
d
Transmission
d
pulse counting
1
5
0
0
0
0
0
1102
12001
13306
5.72532
6.50502
12898
6.50502
13202
6.5033
13113
6.50159
12998
6.49987
13147
6.49815
13175
6.49644
13163
6.49473
13091
6.49301
13102
6.4913
13306
6.48959
12974
6.48789
12914
6.48618
12956
6.48448
13074
6.48277
12940
6.48107
13101
6.47937
13080
6.47767
13016
6.47597
13046
6.47428
12915
6.47258
13189
6.47089
13024
6.46919
12945
6.4675
12941
6.46581
13121
6.46412
12943
6.46244
13097
6.46075
12963
6.45906
12965
6.45738
13011
6.4557
12991
6.45402
12919
6.45234
12850
6.45066
12889
6.44898
12771
6.44731
12812
6.44563
12994
6.44396
12793
6.44229
12864
6.44062
13020
6.43895
12887
6.43728
12923
6.43561
12909
6.43395
13120
6.43228
13097
6.43062
12732
6.42896
13017
6.4273
13069
6.42564
12939
6.42398
12760
6.42233
12950
6.42067
12925
6.41902
13077
6.41737
12770
6.41572
12903
6.41407
12978
6.41242
12869
6.41077
12957
6.40912
12823
6.40748
12960
6.40584
12795
6.40419
12923
6.40255
12980
6.40091
12776
6.39927
12844
6.39764
12778
6.396
12822
6.39437
12985
6.39273
12955
6.3911
12998
6.38947
12966
6.38784
12886
6.38621
12859
6.38458
12736
6.38296
13042
6.38133
12921
6.37971
12766
6.37809
12688
6.37647
12928
6.37485
12794
6.37323
12657
6.37161
12671
6.37
12636
6.36838
12607
6.36677
12672
6.36515
12514
6.36354
12754
6.36193
12836
6.36032
12715
6.35872
12759
6.35711
12636
6.35551
12549
6.3539
12597
6.3523
12727
6.3507
12621
6.3491
12940
6.3475
12731
6.3459
12641
6.3443
12698
6.34271
12691
6.34111
12650
6.33952
12920
6.33793
12738
6.33634
12834
6.33475
12788
6.33316
12796
6.33157
12803
6.32999
12476
6.3284
12644
6.32682
12636
6.32524
12577
6.32366
12899
6.32208
12649
6.3205
12492
6.31892
12720
6.31735
12932
6.31577
12734
6.3142
12722
6.31262
12848
6.31105
12812
6.30948
12655
6.30791
12755
6.30634
12892
6.30478
12680
6.30321
12704
6.30165
12562
6.30008
12332
6.29852
12739
6.29696
12667
6.2954
12741
6.29384
12494
6.29228
12526
6.29073
12541
6.28917
12553
6.28762
12829
6.28606
12643
6.28451
12556
6.28296
12673
6.28141
12698
6.27986
12518
6.27832
12792
6.27677
12657
6.27523
12587
6.27368
12828
6.27214
12740
6.2706
12591
6.26906
12744
6.26752
12406
6.26598
12641
6.26444
12480
6.26291
12656
6.26137
12627
6.25984
12624
6.25831
12664
6.25677
12674
6.25524
12616
6.25371
12619
6.25219
12802
6.25066
12703
6.24913
12457
6.24761
12459
6.24609
12631
6.24456
12578
6.24304
12615
6.24152
12452
6.24
12640
6.23848
12767
6.23697
12638
6.23545
12568
6.23394
12633
6.23242
12611
6.23091
12350
6.2294
12742
6.22789
12687
6.22638
12599
6.22487
12610
6.22336
12487
6.22186
12509
6.22035
12533
6.21885
12830
6.21735
12614
6.21585
12467
6.21435
12549
6.21285
12554
6.21135
12564
6.20985
12438
6.20835
12532
6.20686
12443
6.20537
12436
6.20387
12446
6.20238
12455
6.20089
12525
6.1994
12460
6.19791
12546
6.19642
12509
6.19494
12520
6.19345
12569
6.19197
12592
6.19049
12377
6.189
12388
6.18752
12410
6.18604
12452
6.18456
12342
6.18308
12415
6.18161
12527
6.18013
12427
6.17866
12449
6.17718
12385
6.17571
12394
6.17424
12474
6.17277
12679
6.1713
12499
6.16983
12473
6.16836
12512
6.1669
12439
6.16543
12608
6.16397
12459
6.1625
12594
6.16104
12355
6.15958
12395
6.15812
12493
6.15666
12554
6.1552
12629
6.15375
12422
6.15229
12330
6.15084
12505
6.14938
12366
6.14793
12624
6.14648
12286
6.14503
12581
6.14358
12501
6.14213
12477
6.14068
12497
6.13923
12304
6.13779
12446
6.13634
12284
6.1349
12451
6.13346
12620
6.13202
12209
6.13058
12395
6.12914
12455
6.1277
12226
6.12626
12419
6.12482
12389
6.12339
12410
6.12195
12540
6.12052
12609
6.11909
12393
6.11766
12343
6.11623
12364
6.1148
12498
6.11337
12314
6.11194
12423
6.11051
12401
6.10909
12530
6.10766
12671
6.10624
12468
6.10482
12499
6.1034
12286
6.10198
12565
6.10056
12243
6.09914
12374
6.09772
12380
6.0963
12528
6.09489
12329
6.09347
12260
6.09206
12243
6.09065
12399
6.08924
12497
6.08782
12556
6.08641
12326
6.08501
12441
6.0836
12395
6.08219
12608
6.08079
12314
6.07938
12287
6.07798
12389
6.07657
12285
6.07517
12449
6.07377
12287
6.07237
12385
6.07097
12212
6.06957
12313
6.06818
12235
6.06678
12328
6.06539
12584
6.06399
12527
6.0626
12445
6.06121
12362
6.05982
12401
6.05843
12339
6.05704
12387
6.05565
12461
6.05426
12452
6.05287
12095
6.05149
12340
6.0501
12337
6.04872
12416
6.04734
12436
6.04596
12237
6.04458
12415
6.0432
12225
6.04182
12301
6.04044
12445
6.03906
12349
6.03769
12293
6.03631
12369
6.03494
12310
6.03356
12398
6.03219
12201
6.03082
12185
6.02945
12364
6.02808
12450
6.02671
12384
6.02534
12334
6.02398
12196
6.02261
12481
6.02125
12386
6.01988
12431
6.01852
12347
6.01716
12338
6.0158
12368
6.01444
12394
6.01308
12259
6.01172
12183
6.01036
12155
6.009
12512
6.00765
12392
6.00629
12231
6.00494
12327
6.00359
12556
6.00223
12212
6.00088
12439
5.99953
12429
5.99818
12326
5.99684
12356
5.99549
12123
5.99414
12302
5.9928
12269
5.99145
12177
5.99011
12503
5.98876
12335
5.98742
12366
5.98608
12398
5.98474
12226
5.9834
12226
5.98206
12227
5.98073
12174
5.97939
12387
5.97805
12282
5.97672
12273
5.97539
12372
5.97405
12359
5.97272
12209
5.97139
12318
5.97006
12400
5.96873
12354
5.9674
12310
5.96607
12304
5.96475
12312
5.96342
12414
5.9621
12266
5.96077
12199
5.95945
12001
5.95813
12587
5.9568
12180
5.95548
12262
5.95416
12240
5.95284
12513
5.95153
12285
5.95021
12189
5.94889
12183
5.94758
12360
5.94626
12464
5.94495
12328
5.94364
12125
5.94233
12436
5.94101
12260
5.9397
12283
5.9384
12473
5.93709
12460
5.93578
12229
5.93447
12368
5.93317
12282
5.93186
12107
5.93056
12167
5.92925
12272
5.92795
12384
5.92665
12236
5.92535
12282
5.92405
12089
5.92275
12199
5.92145
12187
5.92016
12424
5.91886
12291
5.91756
12260
5.91627
12207
5.91498
12410
5.91368
12133
5.91239
12247
5.9111
12380
5.90981
12395
5.90852
12348
5.90723
12344
5.90594
12333
5.90465
12441
5.90337
12269
5.90208
12301
5.9008
12213
5.89952
12398
5.89823
12267
5.89695
12380
5.89567
12535
5.89439
12223
5.89311
12260
5.89183
12251
5.89055
12360
5.88928
12203
5.888
12190
5.88672
12223
5.88545
12393
5.88418
12234
5.8829
12211
5.88163
12331
5.88036
12357
5.87909
12743
5.87782
12594
5.87655
12459
5.87528
12456
5.87402
12534
5.87275
12520
5.87148
12281
5.87022
12688
5.86895
12276
5.86769
12513
5.86643
12487
5.86517
12445
5.86391
12469
5.86265
12641
5.86139
12463
5.86013
12684
5.85887
12611
5.85762
12590
5.85636
12598
5.85511
12638
5.85385
12659
5.8526
12288
5.85135
12561
5.85009
12545
5.84884
12594
5.84759
12541
5.84634
12496
5.8451
12648
5.84385
12686
5.8426
12541
5.84135
12452
5.84011
12428
5.83886
12745
5.83762
12809
5.83638
12781
5.83514
12768
5.83389
12685
5.83265
12612
5.83141
12532
5.83018
12367
5.82894
12746
5.8277
12675
5.82646
12547
5.82523
12544
5.82399
12451
5.82276
12610
5.82152
12692
5.82029
12504
5.81906
12696
5.81783
12889
5.8166
12498
5.81537
12621
5.81414
12635
5.81291
12627
5.81168
12739
5.81046
12589
5.80923
12503
5.80801
12694
5.80678
12761
5.80556
12324
5.80434
12636
5.80312
12826
5.8019
12716
5.80067
12555
5.79946
12575
5.79824
12439
5.79702
12609
5.7958
12774
5.79459
12821
5.79337
12683
5.79215
12714
5.79094
12779
5.78973
12662
5.78851
12533
5.7873
12744
5.78609
12789
5.78488
12856
5.78367
12646
5.78246
12794
5.78125
12774
5.78005
12749
5.77884
12733
5.77764
12767
5.77643
12844
5.77523
12538
5.77402
12564
5.77282
12725
5.77162
12780
5.77042
12723
5.76922
12641
5.76802
12743
5.76682
12724
5.76562
12756
5.76442
12558
5.76322
12647
5.76203
12661
5.76083
12703
5.75964
12694
5.75844
12930
5.75725
12784
5.75606
12847
5.75487
12646
5.75368
12848
5.75249
12772
5.7513
12610
5.75011
12639
5.74892
12379
5.74773
12770
5.74655
12581
5.74536
12732
5.74418
12486
5.74299
12482
5.74181
12427
5.74063
12766
5.73944
12613
5.73826
12754
5.73708
12542
5.7359
12643
5.73472
12582
5.73355
12623
5.73237
12548
5.73119
12477
5.73001
12692
5.72884
12540
5.72766
12660
5.72649
12503
5.72532
O1s
ZnO_0B_XPS
2011
11
25
9
2
29
0
8
File = Z:\ZnO_0B_20111123.xml
Group = ZnO_0B_XPS
First of group = 0
Analyzer lens = High:1.5kV
Analyzer slit = 1:6x12\1:6x12
Scan mode = FixedAnalyzerTransmission
Kinetic energy start = 708.6
Kinetic energy base = 0
XPS
1
0
0
0
Mg
1253.6
0.000000
0
0
45.000000
0
FAT
20
1
4.5432
0
0
0
0
0
O1s

-1
kinetic energy
eV
708.6
0.1
2
counts
d
Transmission
d
pulse counting
1
10
0
0
0
0
0
502
13887
80858
3.31256
3.37086
16890
3.37086
16734
3.37062
16748
3.37038
16767
3.37015
16892
3.36991
16568
3.36967
16712
3.36943
16752
3.36919
16255
3.36895
16292
3.36871
16461
3.36847
16383
3.36823
16617
3.36799
16147
3.36776
16389
3.36752
16170
3.36728
16349
3.36704
16283
3.3668
16177
3.36656
16111
3.36632
16032
3.36609
16164
3.36585
15879
3.36561
15872
3.36537
15866
3.36513
15954
3.36489
15745
3.36466
15975
3.36442
15744
3.36418
15811
3.36394
15810
3.3637
15680
3.36347
15591
3.36323
15871
3.36299
15739
3.36275
15659
3.36252
15606
3.36228
15641
3.36204
15774
3.3618
15689
3.36157
15609
3.36133
15642
3.36109
15448
3.36085
15671
3.36062
15720
3.36038
15508
3.36014
15471
3.35991
15651
3.35967
15427
3.35943
15630
3.35919
15798
3.35896
15474
3.35872
15608
3.35848
15573
3.35825
15444
3.35801
15867
3.35777
15779
3.35754
15235
3.3573
15403
3.35706
15606
3.35683
15292
3.35659
15378
3.35635
15441
3.35612
15321
3.35588
15431
3.35565
15612
3.35541
15533
3.35517
15483
3.35494
15684
3.3547
15564
3.35447
15526
3.35423
15387
3.35399
15342
3.35376
15547
3.35352
15463
3.35329
15363
3.35305
15701
3.35282
15680
3.35258
15512
3.35234
15731
3.35211
15720
3.35187
15658
3.35164
15828
3.3514
15952
3.35117
16080
3.35093
16319
3.3507
16337
3.35046
16435
3.35023
16274
3.34999
16747
3.34976
16866
3.34952
17265
3.34929
17331
3.34905
17707
3.34882
18079
3.34858
18532
3.34835
19271
3.34811
20013
3.34788
21209
3.34765
22152
3.34741
23278
3.34718
25207
3.34694
27059
3.34671
29580
3.34647
32247
3.34624
35257
3.34601
39781
3.34577
43435
3.34554
47858
3.3453
53429
3.34507
58138
3.34484
63363
3.3446
68391
3.34437
72535
3.34413
76029
3.3439
79077
3.34367
80858
3.34343
80713
3.3432
80092
3.34297
77839
3.34273
75121
3.3425
70754
3.34227
66373
3.34203
61462
3.3418
57103
3.34157
52049
3.34133
47209
3.3411
43159
3.34087
39380
3.34063
35747
3.3404
32680
3.34017
29446
3.33993
27373
3.3397
25664
3.33947
23558
3.33924
22268
3.339
21043
3.33877
20051
3.33854
19029
3.33831
18329
3.33807
17791
3.33784
17430
3.33761
17140
3.33738
16844
3.33714
16817
3.33691
16466
3.33668
16385
3.33645
16275
3.33621
16158
3.33598
15941
3.33575
16064
3.33552
15795
3.33529
15836
3.33506
15628
3.33482
15727
3.33459
15708
3.33436
15513
3.33413
15433
3.3339
15554
3.33366
15267
3.33343
15367
3.3332
15398
3.33297
15340
3.33274
15512
3.33251
15721
3.33228
15265
3.33205
15323
3.33181
15076
3.33158
15210
3.33135
15158
3.33112
15112
3.33089
14978
3.33066
15025
3.33043
14938
3.3302
14810
3.32997
14947
3.32974
14969
3.3295
14893
3.32927
14697
3.32904
14798
3.32881
14788
3.32858
15104
3.32835
14909
3.32812
15195
3.32789
15055
3.32766
15363
3.32743
15402
3.3272
15536
3.32697
15683
3.32674
15944
3.32651
16653
3.32628
16733
3.32605
17066
3.32582
17457
3.32559
17849
3.32536
18237
3.32513
18726
3.3249
18907
3.32467
19488
3.32444
19567
3.32421
19898
3.32398
19731
3.32375
20062
3.32352
19705
3.32329
19812
3.32306
19471
3.32283
19264
3.32261
19116
3.32238
18926
3.32215
18888
3.32192
18558
3.32169
18367
3.32146
18309
3.32123
18123
3.321
18048
3.32077
18289
3.32054
17972
3.32032
18106
3.32009
18018
3.31986
17772
3.31963
17728
3.3194
17364
3.31917
17195
3.31894
17007
3.31872
16805
3.31849
16703
3.31826
16443
3.31803
16081
3.3178
15673
3.31757
15558
3.31735
15222
3.31712
15238
3.31689
14777
3.31666
14760
3.31643
14698
3.31621
14581
3.31598
14492
3.31575
14349
3.31552
14363
3.31529
14272
3.31507
13956
3.31484
14143
3.31461
14213
3.31438
14136
3.31416
14013
3.31393
13991
3.3137
14136
3.31347
14145
3.31325
13887
3.31302
14022
3.31279
14181
3.31256
Si2p+Zn3p
ZnO_0B_XPS
2011
11
25
9
7
48
0
8
File = Z:\ZnO_0B_20111123.xml
Group = ZnO_0B_XPS
First of group = 0
Analyzer lens = High:1.5kV
Analyzer slit = 1:6x12\1:6x12
Scan mode = FixedAnalyzerTransmission
Kinetic energy start = 1138.6
Kinetic energy base = 0
XPS
1
0
0
0
Mg
1253.6
0.000000
0
0
45.000000
0
FAT
20
1
4.5432
0
0
0
0
0
Si2p+Zn3p

-1
kinetic energy
eV
1138.6
0.1
2
counts
d
Transmission
d
pulse counting
1
10
0
0
0
0
0
802
2246
49065
2.61036
2.656
10371
2.656
10008
2.65588
9852
2.65576
9804
2.65565
9493
2.65553
9204
2.65541
9200
2.65529
9054
2.65518
9088
2.65506
8949
2.65494
8738
2.65483
8727
2.65471
8541
2.65459
8644
2.65448
8280
2.65436
8251
2.65424
8116
2.65413
8000
2.65401
8014
2.65389
7795
2.65377
7688
2.65366
7611
2.65354
7611
2.65342
7534
2.65331
7558
2.65319
7396
2.65307
7354
2.65296
7197
2.65284
7388
2.65272
7241
2.65261
7227
2.65249
7035
2.65237
7116
2.65226
7230
2.65214
7019
2.65202
6889
2.65191
6933
2.65179
6864
2.65167
6898
2.65156
6988
2.65144
6894
2.65133
6926
2.65121
6907
2.65109
6743
2.65098
6777
2.65086
6731
2.65074
6572
2.65063
6854
2.65051
6591
2.65039
6607
2.65028
6640
2.65016
6602
2.65004
6647
2.64993
6668
2.64981
6689
2.6497
6542
2.64958
6579
2.64946
6775
2.64935
6633
2.64923
6507
2.64911
6572
2.649
6773
2.64888
6750
2.64877
6583
2.64865
6585
2.64853
6548
2.64842
6555
2.6483
6581
2.64819
6646
2.64807
6391
2.64795
6596
2.64784
6604
2.64772
6500
2.64761
6515
2.64749
6508
2.64737
6381
2.64726
6355
2.64714
6315
2.64703
6330
2.64691
6473
2.64679
6363
2.64668
6176
2.64656
6158
2.64645
5993
2.64633
6199
2.64621
6184
2.6461
6099
2.64598
6032
2.64587
6056
2.64575
5986
2.64564
6235
2.64552
6129
2.6454
6212
2.64529
6075
2.64517
6284
2.64506
6504
2.64494
6704
2.64483
6808
2.64471
6967
2.64459
7426
2.64448
7733
2.64436
8318
2.64425
8668
2.64413
9439
2.64402
9794
2.6439
10120
2.64379
11041
2.64367
11299
2.64356
11626
2.64344
12082
2.64332
12393
2.64321
12482
2.64309
12239
2.64298
12245
2.64286
12050
2.64275
11680
2.64263
11244
2.64252
10843
2.6424
10545
2.64229
9839
2.64217
9409
2.64206
8966
2.64194
8532
2.64182
8213
2.64171
8043
2.64159
7863
2.64148
7591
2.64136
7429
2.64125
7339
2.64113
7231
2.64102
7169
2.6409
7282
2.64079
7359
2.64067
7649
2.64056
7705
2.64044
8371
2.64033
8848
2.64021
9707
2.6401
10877
2.63998
12150
2.63987
14183
2.63975
16900
2.63964
19901
2.63952
23972
2.63941
28322
2.63929
32781
2.63918
36829
2.63906
40662
2.63895
43769
2.63883
46121
2.63872
47771
2.6386
48966
2.63849
49065
2.63837
47563
2.63826
43282
2.63815
36927
2.63803
29640
2.63792
22460
2.6378
16416
2.63769
12437
2.63757
10028
2.63746
8290
2.63734
7103
2.63723
6332
2.63711
5806
2.637
5242
2.63688
4933
2.63677
4816
2.63665
4354
2.63654
4412
2.63643
4208
2.63631
4077
2.6362
3942
2.63608
3824
2.63597
3860
2.63585
3617
2.63574
3796
2.63562
3691
2.63551
3560
2.6354
3566
2.63528
3570
2.63517
3617
2.63505
3501
2.63494
3518
2.63482
3489
2.63471
3511
2.63459
3542
2.63448
3698
2.63437
3692
2.63425
3641
2.63414
3806
2.63402
3853
2.63391
3904
2.6338
3893
2.63368
4025
2.63357
3906
2.63345
4065
2.63334
3981
2.63322
3881
2.63311
3975
2.633
3978
2.63288
4021
2.63277
3916
2.63265
3839
2.63254
3780
2.63243
3666
2.63231
3611
2.6322
3453
2.63208
3541
2.63197
3476
2.63186
3497
2.63174
3496
2.63163
3406
2.63151
3418
2.6314
3361
2.63129
3373
2.63117
3405
2.63106
3369
2.63094
3302
2.63083
3450
2.63072
3412
2.6306
3440
2.63049
3644
2.63038
3716
2.63026
3725
2.63015
4013
2.63003
4232
2.62992
4652
2.62981
4918
2.62969
5250
2.62958
5506
2.62947
5817
2.62935
6035
2.62924
6307
2.62913
6463
2.62901
6621
2.6289
6461
2.62879
6379
2.62867
5981
2.62856
5565
2.62844
5265
2.62833
4826
2.62822
4492
2.6281
4446
2.62799
4224
2.62788
4217
2.62776
4372
2.62765
4499
2.62754
4461
2.62742
4607
2.62731
4559
2.6272
4618
2.62708
4816
2.62697
4681
2.62686
4531
2.62674
4447
2.62663
4308
2.62652
3995
2.6264
3784
2.62629
3543
2.62618
3383
2.62606
3068
2.62595
2996
2.62584
2907
2.62572
2735
2.62561
2786
2.6255
2726
2.62539
2637
2.62527
2659
2.62516
2704
2.62505
2560
2.62493
2551
2.62482
2640
2.62471
2621
2.62459
2549
2.62448
2525
2.62437
2495
2.62426
2478
2.62414
2512
2.62403
2541
2.62392
2454
2.6238
2441
2.62369
2459
2.62358
2555
2.62346
2390
2.62335
2422
2.62324
2504
2.62313
2590
2.62301
2393
2.6229
2464
2.62279
2512
2.62268
2485
2.62256
2378
2.62245
2521
2.62234
2527
2.62222
2402
2.62211
2342
2.622
2469
2.62189
2454
2.62177
2433
2.62166
2493
2.62155
2426
2.62144
2383
2.62132
2443
2.62121
2466
2.6211
2504
2.62099
2524
2.62087
2495
2.62076
2527
2.62065
2533
2.62054
2483
2.62042
2601
2.62031
2416
2.6202
2481
2.62009
2479
2.61997
2508
2.61986
2581
2.61975
2596
2.61964
2643
2.61952
2537
2.61941
2621
2.6193
2662
2.61919
2582
2.61907
2577
2.61896
2663
2.61885
2595
2.61874
2663
2.61863
2628
2.61851
2629
2.6184
2570
2.61829
2627
2.61818
2541
2.61806
2611
2.61795
2546
2.61784
2526
2.61773
2520
2.61762
2476
2.6175
2470
2.61739
2472
2.61728
2520
2.61717
2534
2.61706
2469
2.61694
2480
2.61683
2497
2.61672
2496
2.61661
2470
2.6165
2548
2.61638
2462
2.61627
2464
2.61616
2515
2.61605
2592
2.61594
2565
2.61582
2528
2.61571
2620
2.6156
2635
2.61549
2547
2.61538
2574
2.61527
2450
2.61515
2586
2.61504
2560
2.61493
2526
2.61482
2456
2.61471
2401
2.61459
2466
2.61448
2391
2.61437
2421
2.61426
2393
2.61415
2377
2.61404
2336
2.61392
2435
2.61381
2363
2.6137
2366
2.61359
2393
2.61348
2324
2.61337
2450
2.61326
2342
2.61314
2258
2.61303
2246
2.61292
2301
2.61281
2364
2.6127
2385
2.61259
2407
2.61247
2268
2.61236
2380
2.61225
2333
2.61214
2275
2.61203
2368
2.61192
2302
2.61181
2338
2.6117
2351
2.61158
2328
2.61147
2354
2.61136
2366
2.61125
2310
2.61114
2323
2.61103
2382
2.61092
2307
2.6108
2385
2.61069
2415
2.61058
2322
2.61047
2366
2.61036
Si2s+Zn3s
ZnO_0B_XPS
2011
11
25
9
15
37
0
8
File = Z:\ZnO_0B_20111123.xml
Group = ZnO_0B_XPS
First of group = 0
Analyzer lens = High:1.5kV
Analyzer slit = 1:6x12\1:6x12
Scan mode = FixedAnalyzerTransmission
Kinetic energy start = 1088.6
Kinetic energy base = 0
XPS
1
0
0
0
Mg
1253.6
0.000000
0
0
45.000000
0
FAT
20
1
4.5432
0
0
0
0
0
Si2s+Zn3s

-1
kinetic energy
eV
1088.6
0.1
2
counts
d
Transmission
d
pulse counting
1
5
0
0
0
0
0
702
4795
21132
2.67374
2.71656
7759
2.71656
7827
2.71643
7790
2.71631
7794
2.71618
7519
2.71606
7737
2.71593
7697
2.71581
7460
2.71568
7344
2.71556
7447
2.71543
7336
2.71531
7395
2.71518
7387
2.71506
7406
2.71493
7249
2.71481
7235
2.71468
7282
2.71456
7334
2.71443
7373
2.71431
7189
2.71418
7226
2.71406
6951
2.71393
7211
2.71381
7215
2.71368
7221
2.71356
7176
2.71343
6959
2.71331
6963
2.71318
7113
2.71306
7050
2.71293
7102
2.71281
7067
2.71268
6973
2.71256
7182
2.71243
6946
2.71231
6932
2.71218
6810
2.71206
6938
2.71193
7006
2.71181
6777
2.71168
6789
2.71156
6985
2.71144
7030
2.71131
6899
2.71119
6893
2.71106
6999
2.71094
7046
2.71081
6919
2.71069
6858
2.71056
6900
2.71044
6872
2.71031
6955
2.71019
6955
2.71007
7015
2.70994
7034
2.70982
7101
2.70969
7096
2.70957
6907
2.70944
7168
2.70932
6948
2.7092
6902
2.70907
7043
2.70895
6886
2.70882
6880
2.7087
6938
2.70857
7054
2.70845
6966
2.70833
6968
2.7082
6976
2.70808
6948
2.70795
6981
2.70783
6966
2.70771
6873
2.70758
7056
2.70746
6984
2.70733
7040
2.70721
7001
2.70709
6918
2.70696
7068
2.70684
7076
2.70671
7062
2.70659
7116
2.70647
7293
2.70634
7182
2.70622
7400
2.70609
7477
2.70597
7409
2.70585
7457
2.70572
7727
2.7056
7701
2.70547
7880
2.70535
8000
2.70523
8086
2.7051
8179
2.70498
8419
2.70486
8490
2.70473
8589
2.70461
8582
2.70449
8880
2.70436
8896
2.70424
9016
2.70411
9007
2.70399
9128
2.70387
9061
2.70374
9072
2.70362
9057
2.7035
8941
2.70337
9046
2.70325
9043
2.70313
8935
2.703
8885
2.70288
8729
2.70276
8826
2.70263
8772
2.70251
8791
2.70239
8668
2.70226
8798
2.70214
8532
2.70202
8968
2.70189
8906
2.70177
9000
2.70165
9176
2.70152
9363
2.7014
9947
2.70128
9814
2.70115
10366
2.70103
10865
2.70091
11306
2.70078
11870
2.70066
12779
2.70054
13532
2.70041
14762
2.70029
15989
2.70017
16891
2.70005
18265
2.69992
19385
2.6998
20429
2.69968
20946
2.69955
21132
2.69943
21123
2.69931
20577
2.69918
20121
2.69906
18704
2.69894
17137
2.69882
16018
2.69869
14420
2.69857
13399
2.69845
12130
2.69832
11177
2.6982
10309
2.69808
9614
2.69796
9205
2.69783
8865
2.69771
8335
2.69759
7971
2.69747
7619
2.69734
7445
2.69722
7281
2.6971
7343
2.69698
7041
2.69685
6847
2.69673
6780
2.69661
6650
2.69648
6631
2.69636
6482
2.69624
6344
2.69612
6218
2.69599
6156
2.69587
6135
2.69575
6113
2.69563
6055
2.6955
6023
2.69538
6011
2.69526
5937
2.69514
5912
2.69502
5895
2.69489
5935
2.69477
5796
2.69465
6006
2.69453
6076
2.6944
6057
2.69428
5914
2.69416
6017
2.69404
5838
2.69392
5914
2.69379
5847
2.69367
6067
2.69355
5818
2.69343
5700
2.6933
5779
2.69318
5791
2.69306
5763
2.69294
5722
2.69282
5779
2.69269
5679
2.69257
5682
2.69245
5744
2.69233
5625
2.69221
5611
2.69208
5728
2.69196
5665
2.69184
5696
2.69172
5580
2.6916
5675
2.69147
5603
2.69135
5564
2.69123
5803
2.69111
5568
2.69099
5778
2.69087
5638
2.69074
5666
2.69062
5683
2.6905
6030
2.69038
5821
2.69026
5962
2.69014
5979
2.69001
6083
2.68989
6264
2.68977
6365
2.68965
6411
2.68953
6494
2.68941
6539
2.68928
6679
2.68916
6733
2.68904
6537
2.68892
6554
2.6888
6325
2.68868
6428
2.68855
6169
2.68843
6103
2.68831
6141
2.68819
6083
2.68807
6032
2.68795
6045
2.68783
6149
2.6877
6107
2.68758
6107
2.68746
6013
2.68734
6062
2.68722
6021
2.6871
6111
2.68698
5975
2.68686
6031
2.68673
5916
2.68661
5895
2.68649
5662
2.68637
5804
2.68625
5678
2.68613
5574
2.68601
5564
2.68589
5494
2.68577
5490
2.68564
5449
2.68552
5489
2.6854
5443
2.68528
5405
2.68516
5437
2.68504
5391
2.68492
5390
2.6848
5356
2.68468
5301
2.68456
5399
2.68443
5491
2.68431
5348
2.68419
5395
2.68407
5450
2.68395
5438
2.68383
5349
2.68371
5495
2.68359
5385
2.68347
5452
2.68335
5453
2.68323
5476
2.68311
5404
2.68298
5423
2.68286
5479
2.68274
5536
2.68262
5567
2.6825
5475
2.68238
5512
2.68226
5607
2.68214
5521
2.68202
5659
2.6819
5635
2.68178
5662
2.68166
5760
2.68154
5630
2.68142
5779
2.6813
5608
2.68118
5804
2.68106
5705
2.68094
5748
2.68081
5717
2.68069
5784
2.68057
5749
2.68045
5950
2.68033
5800
2.68021
5848
2.68009
5830
2.67997
5852
2.67985
5908
2.67973
5912
2.67961
5946
2.67949
5803
2.67937
5838
2.67925
5908
2.67913
5696
2.67901
5899
2.67889
5794
2.67877
5822
2.67865
5931
2.67853
5782
2.67841
5839
2.67829
5857
2.67817
5881
2.67805
5698
2.67793
5705
2.67781
5712
2.67769
5675
2.67757
5634
2.67745
5649
2.67733
5599
2.67721
5582
2.67709
5659
2.67697
5449
2.67685
5544
2.67673
5340
2.67661
5329
2.67649
5367
2.67637
5482
2.67625
5457
2.67613
5182
2.67601
5212
2.67589
5298
2.67577
5224
2.67565
5260
2.67553
5282
2.67541
5131
2.67529
5185
2.67517
5028
2.67505
5038
2.67493
5170
2.67481
5071
2.67469
4931
2.67458
4973
2.67446
4998
2.67434
5018
2.67422
4856
2.6741
4990
2.67398
4795
2.67386
4898
2.67374
HeI_0V
ZnO_0B_UPS
2011
11
25
14
25
45
0
8
File = Z:\ZnO_0B_20111123.xml
Group = ZnO_0B_UPS
First of group = 1
Analyzer lens = High:400V
Analyzer slit = 1:6x12\1:6x12
Scan mode = FixedAnalyzerTransmission
Kinetic energy start = 4.5432
Kinetic energy base = 0
UPS
1
0
0
0
HeI
21.2182
0.000000
0
0
45.000000
0
FAT
1
1
4.5432
0
0
0
0
0
HeI_0V

-1
kinetic energy
eV
4.5432
0.05
2
counts
d
Transmission
d
pulse counting
0.1
10
0
0
0
0
0
850
13
666319
0.217186
4.47214
400
1
403
4.47214
710
3.16228
1312
2.58199
2494
2.23607
4923
2
8607
1.82574
16477
1.69031
29269
1.58114
43953
1.49071
59791
1.41421
81637
1.3484
102657
1.29099
112938
1.24035
126517
1.19523
146255
1.1547
161292
1.11803
159112
1.08465
167542
1.05409
179750
1.02598
189651
1
196418
0.9759
192813
0.953463
207991
0.932505
213596
0.912871
219180
0.894427
214072
0.877058
218676
0.860663
221947
0.845154
224877
0.830455
223617
0.816497
231564
0.803219
233159
0.790569
234569
0.778499
228446
0.766965
233054
0.755929
236555
0.745356
240471
0.735215
237218
0.725476
244301
0.716115
247023
0.707107
254853
0.69843
255976
0.690066
255557
0.681994
260862
0.6742
260025
0.666667
263630
0.65938
265687
0.652328
276890
0.645497
279429
0.638877
283255
0.632456
286213
0.626224
293081
0.620174
296751
0.614295
299791
0.608581
306227
0.603023
313118
0.597614
320065
0.592349
323686
0.58722
331101
0.582223
339157
0.57735
346565
0.572598
355512
0.567962
357524
0.563436
365967
0.559017
376267
0.5547
380588
0.550482
384636
0.546358
392977
0.542326
404498
0.538382
407426
0.534522
409611
0.530745
415426
0.527046
423832
0.523424
428365
0.519875
425827
0.516398
432131
0.512989
433934
0.509647
434172
0.50637
437541
0.503155
435618
0.5
434564
0.496904
432040
0.493865
428886
0.490881
429145
0.48795
428243
0.485071
418390
0.482243
416217
0.479463
413924
0.476731
413400
0.474045
409619
0.471405
398814
0.468807
397743
0.466252
393780
0.463739
385675
0.461266
379656
0.458831
384701
0.456435
381650
0.454077
375642
0.451754
375595
0.449467
373669
0.447214
372437
0.444994
376633
0.442807
377711
0.440653
380064
0.438529
384781
0.436436
389344
0.434372
395490
0.432338
400947
0.430331
408155
0.428353
410255
0.426401
417722
0.424476
424525
0.422577
433260
0.420703
443335
0.418854
452667
0.417029
459064
0.415227
466487
0.413449
471114
0.411693
477741
0.40996
480761
0.408248
489239
0.406558
497302
0.404888
509527
0.403239
511491
0.40161
524156
0.4
530194
0.39841
529935
0.396838
538656
0.395285
544104
0.39375
550977
0.392232
555314
0.390732
568050
0.389249
571248
0.387783
577616
0.386334
580521
0.3849
588686
0.383482
596509
0.38208
597384
0.380693
600865
0.379322
603428
0.377964
613031
0.376622
620274
0.375293
616476
0.373979
623894
0.372678
630156
0.371391
638563
0.370117
640304
0.368856
641266
0.367607
650196
0.366372
656917
0.365148
657598
0.363937
655785
0.362738
661474
0.361551
660764
0.360375
665594
0.359211
666319
0.358057
660626
0.356915
656534
0.355784
657934
0.354663
653777
0.353553
654347
0.352454
645140
0.351364
640306
0.350285
637873
0.349215
630200
0.348155
633832
0.347105
623277
0.346064
615616
0.345033
609259
0.34401
604961
0.342997
599233
0.341993
585456
0.340997
577215
0.34001
577249
0.339032
569759
0.338062
566394
0.3371
560911
0.336146
551253
0.335201
538543
0.334263
530523
0.333333
520071
0.332411
511275
0.331497
502444
0.33059
489325
0.32969
475911
0.328798
461483
0.327913
439126
0.327035
425308
0.326164
407103
0.3253
390921
0.324443
371476
0.323592
351396
0.322749
335002
0.321911
316300
0.321081
296336
0.320256
275347
0.319438
259226
0.318626
240867
0.317821
223469
0.317021
207636
0.316228
194020
0.31544
180396
0.314658
167438
0.313882
154553
0.313112
145355
0.312348
134515
0.311588
127103
0.310835
118702
0.310087
112230
0.309344
105569
0.308607
98090
0.307875
93498
0.307148
87770
0.306426
82200
0.305709
77932
0.304997
73684
0.30429
69527
0.303588
65715
0.302891
61961
0.302199
58847
0.301511
56107
0.300828
53699
0.30015
51099
0.299476
48387
0.298807
46216
0.298142
44544
0.297482
42164
0.296826
40903
0.296174
39071
0.295527
37669
0.294884
35639
0.294245
34599
0.29361
32979
0.292979
31466
0.292353
30297
0.29173
29070
0.291111
28068
0.290496
26538
0.289886
25569
0.289278
24442
0.288675
23360
0.288076
21904
0.28748
21216
0.286888
20371
0.286299
19116
0.285714
17909
0.285133
16743
0.284555
15935
0.283981
14594
0.28341
13730
0.282843
12951
0.282279
11862
0.281718
10933
0.281161
10291
0.280607
9463
0.280056
8726
0.279508
7960
0.278964
7099
0.278423
6654
0.277885
6359
0.27735
5877
0.276818
5569
0.276289
5195
0.275764
4944
0.275241
4696
0.274721
4407
0.274204
4196
0.27369
3881
0.273179
3791
0.272671
3536
0.272166
3340
0.271663
3198
0.271163
2826
0.270666
2878
0.270172
2644
0.26968
2446
0.269191
2263
0.268705
2179
0.268221
2006
0.26774
1888
0.267261
1707
0.266785
1539
0.266312
1369
0.265841
1327
0.265372
1198
0.264906
1109
0.264443
913
0.263982
922
0.263523
817
0.263067
707
0.262613
648
0.262161
544
0.261712
504
0.261265
465
0.26082
416
0.260378
376
0.259938
339
0.2595
324
0.259064
271
0.25863
246
0.258199
227
0.25777
229
0.257343
248
0.256917
205
0.256495
176
0.256074
159
0.255655
158
0.255238
142
0.254824
125
0.254411
137
0.254
119
0.253592
112
0.253185
111
0.25278
100
0.252377
120
0.251976
91
0.251577
69
0.25118
80
0.250785
65
0.250392
78
0.25
57
0.24961
71
0.249222
47
0.248836
45
0.248452
52
0.248069
61
0.247689
38
0.24731
45
0.246932
45
0.246557
36
0.246183
31
0.245811
41
0.24544
42
0.245072
28
0.244704
29
0.244339
23
0.243975
36
0.243613
33
0.243252
28
0.242893
32
0.242536
30
0.24218
29
0.241825
27
0.241473
30
0.241121
37
0.240772
34
0.240424
21
0.240077
15
0.239732
28
0.239388
29
0.239046
27
0.238705
30
0.238366
28
0.238028
27
0.237691
20
0.237356
27
0.237023
30
0.236691
27
0.23636
13
0.23603
20
0.235702
19
0.235376
21
0.23505
22
0.234726
20
0.234404
18
0.234082
13
0.233762
32
0.233444
19
0.233126
14
0.23281
21
0.232495
27
0.232182
20
0.231869
17
0.231558
26
0.231249
25
0.23094
34
0.230633
15
0.230327
21
0.230022
20
0.229718
19
0.229416
19
0.229114
19
0.228814
16
0.228515
17
0.228218
32
0.227921
18
0.227626
32
0.227331
15
0.227038
20
0.226746
20
0.226455
29
0.226166
33
0.225877
19
0.225589
24
0.225303
33
0.225018
30
0.224733
33
0.22445
30
0.224168
25
0.223887
36
0.223607
34
0.223328
23
0.22305
17
0.222773
19
0.222497
27
0.222222
29
0.221948
28
0.221676
29
0.221404
30
0.221133
29
0.220863
24
0.220594
29
0.220326
30
0.220059
30
0.219793
29
0.219529
28
0.219265
23
0.219001
22
0.218739
25
0.218478
27
0.218218
19
0.217959
20
0.2177
23
0.217443
25
0.217186
HeI_2.5V
ZnO_0B_UPS
2011
11
25
13
50
6
0
8
File = Z:\ZnO_0B_20111123.xml
Group = ZnO_0B_UPS
First of group = 0
Analyzer lens = High:400V
Analyzer slit = 1:6x12\1:6x12
Scan mode = FixedAnalyzerTransmission
Kinetic energy start = 4.5432
Kinetic energy base = 0
UPS
1
0
0
0
HeI
21.2182
0.000000
0
0
45.000000
0
FAT
1
1
4.5432
0
0
0
0
0
HeI_2.5V

-1
kinetic energy
eV
4.5432
0.05
2
counts
d
Transmission
d
pulse counting
0.1
10
0
0
0
0
0
970
17
1.40358E+006
0.203279
4.47214
945
1
1228
4.47214
1684
3.16228
2499
2.58199
3276
2.23607
4185
2
5245
1.82574
6820
1.69031
9413
1.58114
11877
1.49071
15232
1.41421
23032
1.3484
34560
1.29099
39210
1.24035
42856
1.19523
57325
1.1547
65237
1.11803
66867
1.08465
67073
1.05409
73989
1.02598
158413
1
322465
0.9759
514318
0.953463
692399
0.932505
814296
0.912871
890819
0.894427
952005
0.877058
1.03077E+006
0.860663
1.11125E+006
0.845154
1.17146E+006
0.830455
1.22202E+006
0.816497
1.2635E+006
0.803219
1.30059E+006
0.790569
1.31919E+006
0.778499
1.34864E+006
0.766965
1.37966E+006
0.755929
1.40358E+006
0.745356
1.39238E+006
0.735215
1.37875E+006
0.725476
1.38003E+006
0.716115
1.38197E+006
0.707107
1.37876E+006
0.69843
1.36718E+006
0.690066
1.34167E+006
0.681994
1.32568E+006
0.6742
1.31074E+006
0.666667
1.29945E+006
0.65938
1.28646E+006
0.652328
1.26152E+006
0.645497
1.2373E+006
0.638877
1.21149E+006
0.632456
1.20074E+006
0.626224
1.18431E+006
0.620174
1.15746E+006
0.614295
1.1313E+006
0.608581
1.1077E+006
0.603023
1.08971E+006
0.597614
1.07018E+006
0.592349
1.04998E+006
0.58722
1.02553E+006
0.582223
1.00256E+006
0.57735
983456
0.572598
967380
0.567962
944901
0.563436
925527
0.559017
910471
0.5547
887238
0.550482
864351
0.546358
850750
0.542326
841552
0.538382
825709
0.534522
809082
0.530745
788809
0.527046
777263
0.523424
766969
0.519875
748078
0.516398
738263
0.512989
724950
0.509647
710279
0.50637
704116
0.503155
693315
0.5
682592
0.496904
672674
0.493865
663761
0.490881
657035
0.48795
652985
0.485071
643020
0.482243
633918
0.479463
632633
0.476731
631055
0.474045
626167
0.471405
622577
0.468807
621195
0.466252
621877
0.463739
617465
0.461266
612204
0.458831
619386
0.456435
620150
0.454077
616486
0.451754
620478
0.449467
620639
0.447214
619901
0.444994
629073
0.442807
629638
0.440653
635219
0.438529
638286
0.436436
643370
0.434372
648171
0.432338
657639
0.430331
661128
0.428353
662500
0.426401
670594
0.424476
676085
0.422577
686749
0.420703
696726
0.418854
704475
0.417029
710555
0.415227
714657
0.413449
718088
0.411693
721751
0.40996
724979
0.408248
728049
0.406558
730088
0.404888
737435
0.403239
734565
0.40161
737943
0.4
734993
0.39841
724401
0.396838
723024
0.395285
718232
0.39375
711925
0.392232
703277
0.390732
702599
0.389249
691760
0.387783
681034
0.386334
671594
0.3849
660509
0.383482
652351
0.38208
637753
0.380693
627412
0.379322
614251
0.377964
605503
0.376622
596845
0.375293
581602
0.373979
576020
0.372678
570218
0.371391
568170
0.370117
561406
0.368856
557534
0.367607
559033
0.366372
563147
0.365148
563208
0.363937
562298
0.362738
569570
0.361551
570482
0.360375
581840
0.359211
590167
0.358057
594432
0.356915
594688
0.355784
603407
0.354663
611943
0.353553
619284
0.352454
623285
0.351364
628468
0.350285
632928
0.349215
643233
0.348155
658007
0.347105
661403
0.346064
664538
0.345033
671489
0.34401
677973
0.342997
685062
0.341993
686685
0.340997
690542
0.34001
701891
0.339032
711737
0.338062
719485
0.3371
728602
0.336146
734602
0.335201
734773
0.334263
740258
0.333333
746484
0.332411
753295
0.331497
763186
0.33059
768259
0.32969
772403
0.328798
777268
0.327913
775190
0.327035
780189
0.326164
785865
0.3253
791405
0.324443
795472
0.323592
796052
0.322749
803869
0.321911
809819
0.321081
810038
0.320256
809122
0.319438
820690
0.318626
822801
0.317821
825263
0.317021
825233
0.316228
824348
0.31544
827855
0.314658
831283
0.313882
822149
0.313112
822379
0.312348
817169
0.311588
813649
0.310835
816148
0.310087
814713
0.309344
807354
0.308607
798066
0.307875
796797
0.307148
787929
0.306426
780253
0.305709
773398
0.304997
765455
0.30429
754464
0.303588
745636
0.302891
736148
0.302199
728910
0.301511
720712
0.300828
713668
0.30015
702742
0.299476
690897
0.298807
679300
0.298142
670997
0.297482
660461
0.296826
651703
0.296174
636337
0.295527
622245
0.294884
608926
0.294245
594606
0.29361
576772
0.292979
558323
0.292353
541309
0.29173
520169
0.291111
498759
0.290496
475850
0.289886
455805
0.289278
432623
0.288675
408144
0.288076
383630
0.28748
362494
0.286888
339113
0.286299
315615
0.285714
293396
0.285133
273388
0.284555
256135
0.283981
236648
0.28341
219831
0.282843
206583
0.282279
191075
[...]
518866
0.263067
492332
0.262613
464845
0.262161
438527
0.261712
410232
0.261265
380238
0.26082
355986
0.260378
333209
0.259938
308666
0.2595
285623
0.259064
265469
0.25863
246020
0.258199
229455
0.25777
213205
0.257343
197723
0.256917
183524
0.256495
174530
0.256074
163461
0.255655
153206
0.255238
143488
0.254824
134472
0.254411
126777
0.254
119196
0.253592
111363
0.253185
105694
0.25278
98871
0.252377
92978
0.251976
87526
0.251577
83084
0.25118
78400
0.250785
73266
0.250392
69730
0.25
66158
0.24961
62863
0.249222
59874
0.248836
56920
0.248452
54318
0.248069
51908
0.247689
49339
0.24731
47082
0.246932
44816
0.246557
42851
0.246183
41202
0.245811
39190
0.24544
37316
0.245072
35676
0.244704
34379
0.244339
32952
0.243975
31168
0.243613
29657
0.243252
28205
0.242893
26951
0.242536
25489
0.24218
24519
0.241825
23110
0.241473
21843
0.241121
20393
0.240772
19506
0.240424
17839
0.240077
16562
0.239732
15330
0.239388
14322
0.239046
12995
0.238705
12000
0.238366
11023
0.238028
10049
0.237691
9422
0.237356
8420
0.237023
7985
0.236691
7350
0.23636
6809
0.23603
6354
0.235702
5939
0.235376
5646
0.23505
5390
0.234726
5094
0.234404
4711
0.234082
4451
0.233762
4189
0.233444
4031
0.233126
3744
0.23281
3593
0.232495
3354
0.232182
3035
0.231869
3044
0.231558
2824
0.231249
2651
0.23094
2386
0.230633
2242
0.230327
2035
0.230022
1872
0.229718
1692
0.229416
1499
0.229114
1438
0.228814
1365
0.228515
1170
0.228218
1093
0.227921
991
0.227626
857
0.227331
743
0.227038
682
0.226746
627
0.226455
535
0.226166
472
0.225877
422
0.225589
362
0.225303
357
0.225018
329
0.224733
287
0.22445
276
0.224168
274
0.223887
247
0.223607
221
0.223328
219
0.22305
191
0.222773
199
0.222497
208
0.222222
177
0.221948
178
0.221676
169
0.221404
159
0.221133
132
0.220863
122
0.220594
124
0.220326
98
0.220059
117
0.219793
117
0.219529
100
0.219265
106
0.219001
94
0.218739
75
0.218478
92
0.218218
73
0.217959
70
0.2177
67
0.217443
80
0.217186
66
0.21693
55
0.216676
43
0.216422
59
0.216169
52
0.215917
44
0.215666
58
0.215415
36
0.215166
45
0.214917
53
0.214669
35
0.214423
33
0.214176
50
0.213931
30
0.213687
43
0.213443
37
0.213201
39
0.212959
34
0.212718
34
0.212478
36
0.212238
31
0.212
43
0.211762
43
0.211525
26
0.211289
27
0.211053
32
0.210819
29
0.210585
35
0.210352
26
0.210119
37
0.209888
27
0.209657
33
0.209427
33
0.209198
28
0.208969
31
0.208741
30
0.208514
36
0.208288
24
0.208063
33
0.207838
18
0.207614
24
0.20739
31
0.207168
21
0.206946
33
0.206725
25
0.206504
19
0.206284
38
0.206065
26
0.205847
25
0.205629
23
0.205412
23
0.205196
33
0.20498
27
0.204765
33
0.204551
25
0.204337
33
0.204124
30
0.203912
27
0.2037
28
0.203489
22
0.203279
26
0.203069
32
0.20286
25
0.202652
25
0.202444
26
0.202237
28
0.202031
41
0.201825
38
0.201619
28
0.201415
36
0.201211
37
0.201008
34
0.200805
39
0.200603
40
0.200401
33
0.2002
33
0.2
38
0.1998
39
0.199601
24
0.199403
33
0.199205
37
0.199007
34
0.198811
24
0.198615
40
0.198419
30
0.198224
38
0.19803
35
0.197836
38
0.197642
38
0.19745
39
0.197257
39
0.197066
49
0.196875
43
0.196684
40
0.196494
28
0.196305
39
0.196116
33
0.195928
35
0.19574
39
0.195553
38
0.195366
28
0.19518
32
0.194994
29
0.194809
37
0.194625
29
0.194441
29
0.194257
37
0.194074
35
0.193892
31
0.19371
28
0.193528
HeI_10V
ZnO_0B_UPS
2011
11
25
14
13
37
0
8
File = Z:\ZnO_0B_20111123.xml
Group = ZnO_0B_UPS
First of group = 0
Analyzer lens = High:400V
Analyzer slit = 1:6x12\1:6x12
Scan mode = FixedAnalyzerTransmission
Kinetic energy start = 4.5432
Kinetic energy base = 0
UPS
1
0
0
0
HeI
21.2182
0.000000
0
0
45.000000
0
FAT
1
1
4.5432
0
0
0
0
0
HeI_10V

-1
kinetic energy
eV
4.5432
0.05
2
counts
d
Transmission
d
pulse counting
0.1
10
0
0
0
0
0
1268
15
1.84306E+006
0.177751
4.47214
1025
1
1189
4.47214
2206
3.16228
3081
2.58199
3921
2.23607
4662
2
5088
1.82574
6608
1.69031
8396
1.58114
12883
1.49071
17374
1.41421
21017
1.3484
22701
1.29099
22415
1.24035
21908
1.19523
22569
1.1547
22755
1.11803
20961
1.08465
21868
1.05409
23573
1.02598
26154
1
28990
0.9759
30944
0.953463
36250
0.932505
41061
0.912871
44828
0.894427
46734
0.877058
50541
0.860663
54441
0.845154
57163
0.830455
58076
0.816497
61868
0.803219
60928
0.790569
58607
0.778499
51839
0.766965
47824
0.755929
44451
0.745356
41578
0.735215
37507
0.725476
34184
0.716115
30351
0.707107
28086
0.69843
25618
0.690066
23627
0.681994
23042
0.6742
23603
0.666667
25849
0.65938
28768
0.652328
32321
0.645497
34198
0.638877
36415
0.632456
39756
0.626224
42315
0.620174
44279
0.614295
46080
0.608581
48588
0.603023
50882
0.597614
52716
0.592349
53738
0.58722
54575
0.582223
55447
0.57735
55529
0.572598
55199
0.567962
54248
0.563436
53005
0.559017
51652
0.5547
50470
0.550482
48373
0.546358
47299
0.542326
46776
0.538382
45123
0.534522
43998
0.530745
42409
0.527046
41457
0.523424
40041
0.519875
37943
0.516398
36839
0.512989
35494
0.509647
34058
0.50637
32781
0.503155
32094
0.5
30708
0.496904
29926
0.493865
28621
0.490881
28257
0.48795
27199
0.485071
25683
0.482243
25196
0.479463
24588
0.476731
24239
0.474045
23574
0.471405
22268
0.468807
21669
0.466252
21003
0.463739
20514
0.461266
19258
0.458831
19108
0.456435
18870
0.454077
17836
0.451754
17416
0.449467
16517
0.447214
15853
0.444994
15243
0.442807
14865
0.440653
14178
0.438529
13984
0.436436
13459
0.434372
13100
0.432338
12746
0.430331
12380
0.428353
11842
0.426401
11478
0.424476
11037
0.422577
10788
0.420703
10684
0.418854
10229
0.417029
10073
0.415227
9863
0.413449
9471
0.411693
9268
0.40996
8847
0.408248
8749
0.406558
8614
0.404888
8656
0.403239
8267
0.40161
7862
0.4
7754
0.39841
7501
0.396838
7051
0.395285
6803
0.39375
6380
0.392232
6198
0.390732
5958
0.389249
6003
0.387783
5754
0.386334
5670
0.3849
5516
0.383482
5401
0.38208
5357
0.380693
5234
0.379322
4994
0.377964
4987
0.376622
5079
0.375293
4983
0.373979
4834
0.372678
4918
0.371391
4953
0.370117
4989
0.368856
4921
0.367607
5020
0.366372
5249
0.365148
5255
0.363937
5690
0.362738
5829
0.361551
6513
0.360375
7522
0.359211
8702
0.358057
10131
0.356915
13206
0.355784
18588
0.354663
28782
0.353553
50327
0.352454
88191
0.351364
146360
0.350285
230457
0.349215
314397
0.348155
426422
0.347105
549121
0.346064
657400
0.345033
792776
0.34401
907885
0.342997
1.01455E+006
0.341993
1.09537E+006
0.340997
1.16995E+006
0.34001
1.27018E+006
0.339032
1.36477E+006
0.338062
1.44927E+006
0.3371
1.52332E+006
0.336146
1.58182E+006
0.335201
1.62753E+006
0.334263
1.66808E+006
0.333333
1.71858E+006
0.332411
1.75616E+006
0.331497
1.78921E+006
0.33059
1.80537E+006
0.32969
1.82391E+006
0.328798
1.84181E+006
0.327913
1.83695E+006
0.327035
1.8429E+006
0.326164
1.84306E+006
0.3253
1.83681E+006
0.324443
1.82345E+006
0.323592
1.81131E+006
0.322749
1.7938E+006
0.321911
1.76887E+006
0.321081
1.74287E+006
0.320256
1.72637E+006
0.319438
1.7037E+006
0.318626
1.6853E+006
0.317821
1.65868E+006
0.317021
1.62041E+006
0.316228
1.58041E+006
0.31544
1.55615E+006
0.314658
1.53025E+006
0.313882
1.49231E+006
0.313112
1.45274E+006
0.312348
1.42603E+006
0.311588
1.40161E+006
0.310835
1.37727E+006
0.310087
1.34571E+006
0.309344
1.31639E+006
0.308607
1.28412E+006
0.307875
1.25889E+006
0.307148
1.23066E+006
0.306426
1.20218E+006
0.305709
1.17793E+006
0.304997
1.15061E+006
0.30429
1.13329E+006
0.303588
1.11201E+006
0.302891
1.08664E+006
0.302199
1.06048E+006
0.301511
1.03741E+006
0.300828
1.01935E+006
0.30015
1.0029E+006
0.299476
982861
0.298807
963372
0.298142
948041
0.297482
935924
0.296826
923920
0.296174
907496
0.295527
897384
0.294884
881940
0.294245
873180
0.29361
859899
0.292979
850164
0.292353
838312
0.29173
828853
0.291111
823799
0.290496
820098
0.289886
817120
0.289278
806461
0.288675
799326
0.288076
803694
0.28748
803421
0.286888
795353
0.286299
793323
0.285714
792195
0.285133
796358
0.284555
803756
0.283981
801084
0.28341
801482
0.282843
807740
0.282279
810672
0.281718
815387
0.281161
813585
0.280607
825464
0.280056
836292
0.279508
841592
0.278964
847734
0.278423
852605
0.277885
865625
0.27735
876424
0.276818
882752
0.276289
892286
0.275764
897638
0.275241
911077
0.274721
920873
0.274204
926366
0.27369
932520
0.273179
936654
0.272671
945219
0.272166
944870
0.271663
951747
0.271163
953212
0.270666
948660
0.270172
941796
0.26968
940193
0.269191
942196
0.268705
937115
0.268221
926060
0.26774
918373
0.267261
908574
0.266785
903923
0.266312
891221
0.265841
875828
0.265372
867157
0.264906
857402
0.264443
839763
0.263982
826097
0.263523
806446
0.263067
793963
0.262613
785884
0.262161
779075
0.261712
764040
0.261265
747663
0.26082
741174
0.260378
741741
0.259938
738618
0.2595
728350
0.259064
727384
0.25863
730425
0.258199
735861
0.25777
734974
0.257343
731861
0.256917
744036
0.256495
759492
0.256074
769404
0.255655
773957
0.255238
779186
0.254824
792592
0.254411
804034
0.254
811696
0.253592
825099
0.253185
834252
0.25278
841599
0.252377
856102
0.251976
863282
0.251577
874821
0.25118
883566
0.250785
885862
0.250392
895190
0.25
900397
0.24961
914391
0.249222
927686
0.248836
933203
0.248452
939550
0.248069
952285
0.247689
964059
0.24731
962956
0.246932
969417
0.246557
979813
0.246183
988060
0.245811
996258
0.24544
993612
0.245072
1.00195E+006
0.244704
1.01054E+006
0.244339
1.02171E+006
0.243975
1.02971E+006
0.243613
1.02351E+006
0.243252
1.02656E+006
0.242893
1.03989E+006
0.242536
1.03521E+006
0.24218
1.04693E+006
0.241825
1.05062E+006
0.241473
1.06201E+006
0.241121
1.06961E+006
0.240772
1.06905E+006
0.240424
1.06841E+006
0.240077
1.06639E+006
0.239732
1.07522E+006
0.239388
1.07666E+006
0.239046
1.06578E+006
0.238705
1.0601E+006
0.238366
1.06649E+006
0.238028
1.07458E+006
0.237691
1.06115E+006
0.237356
1.05116E+006
0.237023
1.044E+006
0.236691
1.04655E+006
0.23636
1.04262E+006
0.23603
1.02939E+006
0.235702
1.01475E+006
0.235376
1.0131E+006
0.23505
1.01383E+006
0.234726
1.00157E+006
0.234404
982315
0.234082
970304
0.233762
963754
0.233444
955711
0.233126
945940
0.23281
928419
0.232495
914203
0.232182
906855
0.231869
894215
0.231558
874378
0.231249
861390
0.23094
849653
0.230633
833655
0.230327
816499
0.230022
802328
0.229718
781420
0.229416
757424
0.229114
741587
0.228814
715901
0.228515
692528
0.228218
668008
0.227921
645021
0.227626
615217
0.227331
584953
0.227038
553460
0.226746
524134
0.226455
498305
0.226166
466727
0.225877
437571
0.225589
407578
0.225303
380450
0.225018
352943
0.224733
327310
0.22445
304253
0.224168
283189
0.223887
260750
0.223607
241201
0.223328
225778
0.22305
209029
0.222773
196572
0.222497
183143
0.222222
171767
0.221948
161135
0.221676
149720
0.221404
141316
0.221133
132001
0.220863
125135
0.220594
117294
0.220326
110287
0.220059
104038
0.219793
98157
0.219529
92971
0.219265
87665
0.219001
82210
0.218739
78205
0.218478
73850
0.218218
70740
0.217959
67033
0.2177
64292
0.217443
60855
0.217186
58267
0.21693
56294
0.216676
53220
0.216422
51112
0.216169
48664
0.215917
46942
0.215666
44942
0.215415
43120
0.215166
40834
0.214917
39244
0.214669
37659
0.214423
36259
0.214176
34482
0.213931
32618
0.213687
30917
0.213443
29613
0.213201
27505
0.212959
26482
0.212718
25229
0.212478
23733
0.212238
22075
0.212
20896
0.211762
19561
0.211525
18235
0.211289
16809
0.211053
15501
0.210819
14140
0.210585
12948
0.210352
11769
0.210119
11105
0.209888
10128
0.209657
9463
0.209427
8878
0.209198
8052
0.208969
7554
0.208741
7139
0.208514
6613
0.208288
6381
0.208063
5744
0.207838
5493
0.207614
5379
0.20739
5032
0.207168
4633
0.206946
4456
0.206725
4157
0.206504
3985
0.206284
3737
0.206065
3541
0.205847
3342
0.205629
3067
0.205412
2959
0.205196
2747
0.20498
2520
0.204765
2325
0.204551
2135
0.204337
1998
0.204124
1792
0.203912
1669
0.2037
1459
0.203489
1369
0.203279
1224
0.203069
1112
0.20286
998
0.202652
890
0.202444
784
0.202237
723
0.202031
616
0.201825
537
0.201619
463
0.201415
461
0.201211
395
0.201008
381
0.200805
357
0.200603
287
0.200401
292
0.2002
279
0.2
265
0.1998
269
0.199601
243
0.199403
226
0.199205
199
0.199007
174
0.198811
158
0.198615
154
0.198419
132
0.198224
130
0.19803
143
0.197836
111
0.197642
112
0.19745
112
0.197257
85
0.197066
91
0.196875
83
0.196684
83
0.196494
100
0.196305
83
0.196116
79
0.195928
48
0.19574
73
0.195553
59
0.195366
63
0.19518
55
0.194994
57
0.194809
55
0.194625
47
0.194441
64
0.194257
44
0.194074
36
0.193892
36
0.19371
47
0.193528
40
0.193347
30
0.193167
33
0.192987
47
0.192807
43
0.192629
35
0.19245
33
0.192272
41
0.192095
35
0.191918
40
0.191741
29
0.191565
37
0.19139
32
0.191215
29
0.19104
36
0.190866
31
0.190693
38
0.190519
40
0.190347
39
0.190175
40
0.190003
46
0.189832
25
0.189661
28
0.18949
33
0.189321
28
0.189151
34
0.188982
32
0.188814
27
0.188646
32
0.188478
20
0.188311
28
0.188144
31
0.187978
26
0.187812
15
0.187647
33
0.187482
23
0.187317
17
0.187153
19
0.186989
26
0.186826
33
0.186663
24
0.186501
33
0.186339
30
0.186177
21
0.186016
26
0.185856
23
0.185695
31
0.185535
21
0.185376
24
0.185217
30
0.185058
31
0.1849
29
0.184742
23
0.184585
26
0.184428
26
0.184271
28
0.184115
28
0.183959
37
0.183804
34
0.183649
36
0.183494
33
0.18334
27
0.183186
23
0.183032
36
0.182879
37
0.182727
25
0.182574
33
0.182422
47
0.182271
31
0.182119
27
0.181969
27
0.181818
38
0.181668
32
0.181518
25
0.181369
18
0.18122
31
0.181071
34
0.180923
36
0.180775
28
0.180628
34
0.180481
30
0.180334
39
0.180187
29
0.180041
26
0.179896
29
0.17975
40
0.179605
42
0.179461
29
0.179316
29
0.179172
25
0.179029
35
0.178885
43
0.178743
34
0.1786
36
0.178458
43
0.178316
29
0.178174
23
0.178033
37
0.177892
28
0.177751
HeII
ZnO_0B_UPS
2011
11
25
14
37
25
0
8
File = Z:\ZnO_0B_20111123.xml
Group = ZnO_0B_UPS
First of group = 0
Analyzer lens = High:400V
Analyzer slit = 1:6x12\1:6x12
Scan mode = FixedAnalyzerTransmission
Kinetic energy start = 22.8138
Kinetic energy base = 0
UPS
1
0
0
0
HeII
40.8138
0.000000
0
0
45.000000
0
FAT
10
1
4.5432
0
0
0
0
0
HeII

-1
kinetic energy
eV
22.8138
0.05
2
counts
d
Transmission
d
pulse counting
0.1
10
0
0
0
0
0
922
478
107293
4.92243
7.39816
30813
7.39816
30344
7.38806
30023
7.37799
30073
7.36797
29426
7.358
29462
7.34806
29258
7.33816
28977
7.3283
28552
7.31848
28366
7.3087
28083
7.29896
27764
7.28926
27710
7.27959
27402
7.26997
27252
7.26038
26923
7.25083
27207
7.24132
27030
7.23185
27443
7.22241
27228
7.21301
27801
7.20365
28009
7.19432
28698
7.18503
29146
7.17577
29706
7.16655
30471
7.15737
30985
7.14822
31657
7.13911
32441
7.13003
33346
7.12098
33856
7.11197
34449
7.103
35238
7.09405
35998
7.08515
36516
7.07627
36697
7.06743
37418
7.05862
37758
7.04984
38520
7.0411
37702
7.03239
38783
7.02371
38771
7.01507
38770
7.00645
38489
6.99787
39314
6.98932
39312
6.9808
39217
6.97231
39888
6.96385
39992
6.95542
40167
6.94702
39674
6.93866
39904
6.93032
40468
6.92201
40659
6.91374
40604
6.90549
41070
6.89727
41081
6.88909
41103
6.88093
40909
6.8728
41536
6.86469
41505
6.85662
41838
6.84858
41572
6.84056
41995
6.83257
41940
6.82461
41964
6.81668
42298
6.80877
41759
6.8009
42049
6.79305
42209
6.78522
41988
6.77743
41896
6.76966
41853
6.76191
41839
6.7542
41939
6.74651
42006
6.73884
41748
6.73121
41908
6.7236
41691
6.71601
41612
6.70845
41395
6.70091
41357
6.6934
42039
6.68592
41972
6.67846
41875
6.67103
42334
6.66362
42365
6.65623
42880
6.64887
43498
6.64154
43399
6.63422
43802
6.62694
45112
6.61967
45289
6.61243
46315
6.60522
46984
6.59802
47541
6.59085
48498
6.58371
49354
6.57659
50554
6.56949
51484
6.56241
52634
6.55535
53700
6.54832
54092
6.54132
55730
6.53433
56326
6.52737
57241
6.52042
57646
6.5135
58519
6.50661
59683
6.49973
60230
6.49288
60303
6.48604
60511
6.47923
61378
6.47244
61057
6.46568
61037
6.45893
61028
6.4522
60633
6.4455
60076
6.43881
59263
6.43215
58881
6.42551
58620
6.41889
57635
6.41229
56762
6.4057
55968
6.39914
54539
6.3926
53341
6.38608
52919
6.37958
52360
6.3731
51856
6.36664
51118
6.3602
50370
6.35377
49851
6.34737
49638
6.34099
49801
6.33462
50135
6.32828
50780
6.32195
51242
6.31564
52374
6.30936
52893
6.30309
54571
6.29683
55565
6.2906
56855
6.28439
57994
6.27819
59858
6.27202
61384
6.26586
62452
6.25971
64836
6.25359
65772
6.24749
67187
6.2414
68535
6.23533
70098
6.22928
71407
6.22324
72918
6.21723
73919
6.21123
75099
6.20525
76003
6.19928
76655
6.19333
78203
6.1874
78447
6.18149
79512
6.17559
81048
6.16971
82092
6.16385
82412
6.158
83788
6.15217
84167
6.14636
85040
6.14056
86284
6.13478
87226
6.12902
88477
6.12327
89695
6.11754
90217
6.11183
91060
6.10613
91433
6.10044
92923
6.09477
92891
6.08912
94100
6.08349
95464
6.07787
96745
6.07226
97510
6.06667
98443
6.0611
99185
6.05554
99949
6.04999
101167
6.04446
101910
6.03895
102694
6.03345
103191
6.02797
103862
6.0225
105028
6.01705
104907
6.01161
105870
6.00618
106212
6.00078
106163
5.99538
106337
5.99
107044
5.98463
107293
5.97928
106545
5.97395
105821
5.96862
107158
5.96331
106177
5.95802
105259
5.95274
105626
5.94747
104512
5.94222
104387
5.93698
104286
5.93176
103238
5.92655
102657
5.92135
102073
5.91617
101689
5.911
100984
5.90584
99870
5.9007
99411
5.89557
98607
5.89045
96999
5.88535
96125
5.88026
94678
5.87518
92739
5.87012
91268
5.86507
88844
5.86003
86910
5.85501
84222
5.84999
81476
5.845
78427
5.84001
75114
5.83504
71841
5.83008
68361
5.82513
64702
5.82019
61128
5.81527
57254
5.81036
53211
5.80546
49881
5.80058
46060
5.7957
42607
5.79084
39250
5.78599
36542
5.78116
33726
5.77633
31500
5.77152
28976
5.76672
27548
5.76193
25774
5.75716
23954
5.75239
22543
5.74764
21790
5.7429
20484
5.73817
19498
5.73345
18494
5.72875
17347
5.72405
16760
5.71937
16391
5.7147
15510
5.71004
15238
5.70539
14613
5.70075
14290
5.69612
13668
5.69151
13348
5.68691
12862
5.68231
12619
5.67773
12288
5.67316
11844
5.6686
11764
5.66405
11357
5.65952
11087
5.65499
10719
5.65048
10559
5.64597
10396
5.64148
10443
5.63699
10017
5.63252
9910
5.62806
9669
5.62361
9450
5.61917
9291
5.61474
9125
5.61032
9219
5.60591
8723
5.60151
8395
5.59712
8329
5.59274
7990
5.58837
7896
5.58401
7391
5.57967
7524
5.57533
7223
5.571
7033
5.56668
6640
5.56238
6330
5.55808
6082
5.55379
5805
5.54951
5816
5.54524
5561
5.54099
5446
5.53674
5254
5.5325
5149
5.52827
5121
5.52405
4869
5.51984
4961
5.51564
4960
5.51145
5019
5.50727
5035
5.5031
4917
5.49894
4994
5.49479
5182
5.49064
5140
5.48651
5148
5.48239
5263
5.47827
5319
5.47417
5369
5.47007
5555
5.46598
5575
5.4619
5612
5.45784
5583
5.45378
5820
5.44972
5781
5.44568
5710
5.44165
5885
5.43763
5840
5.43361
5987
5.42961
6000
5.42561
5948
5.42162
6142
5.41764
6086
5.41367
6100
5.40971
6106
5.40575
6144
5.40181
6319
5.39787
6195
5.39394
6261
5.39003
6383
5.38611
6415
5.38221
6533
5.37832
6374
5.37443
6519
5.37056
6547
5.36669
6560
5.36283
6497
5.35898
6729
5.35513
6608
5.3513
6821
5.34747
6712
5.34365
6813
5.33984
6911
5.33604
7004
5.33225
6825
5.32846
6762
5.32468
6946
5.32091
6923
5.31715
7080
5.31339
6896
5.30965
7081
5.30591
6984
5.30218
7087
5.29846
6939
5.29474
6904
5.29103
6952
5.28734
6928
5.28364
6862
5.27996
6826
5.27628
6746
5.27262
6913
5.26896
6795
5.2653
6493
5.26166
6769
5.25802
6502
5.25439
6572
5.25077
6613
5.24715
6522
5.24354
6264
5.23994
6407
5.23635
6301
5.23276
6226
5.22918
5973
5.22561
5896
5.22205
5953
5.21849
5661
5.21494
5576
5.2114
5410
5.20787
5314
5.20434
5202
5.20082
4954
5.19731
4908
5.1938
4682
5.1903
4471
5.18681
4150
5.18332
4093
5.17985
3856
5.17637
3741
5.17291
3551
5.16945
3479
5.166
3219
5.16256
3186
5.15912
3069
5.15569
3019
5.15227
2896
5.14886
2808
5.14545
2768
5.14204
2680
5.13865
2607
5.13526
2641
5.13188
2684
5.1285
2715
5.12513
2549
5.12177
2454
5.11842
2464
5.11507
2529
5.11172
2456
5.10839
2401
5.10506
2348
5.10174
2267
5.09842
2355
5.09511
2274
5.09181
2306
5.08851
2263
5.08522
2162
5.08193
2197
5.07866
2188
5.07538
2214
5.07212
2215
5.06886
2147
5.06561
2200
5.06236
2063
5.05912
2098
5.05589
2123
5.05266
2060
5.04944
2007
5.04622
1955
5.04301
1931
5.03981
1935
5.03661
1895
5.03342
1767
5.03023
1796
5.02706
1704
5.02388
1677
5.02072
1618
5.01755
1628
5.0144
1553
5.01125
1456
5.00811
1331
5.00497
1324
5.00184
1284
4.99871
1192
4.99559
1190
4.99248
1065
4.98937
1069
4.98627
1067
4.98317
964
4.98008
1007
4.977
889
4.97392
871
4.97084
863
4.96778
878
4.96471
807
4.96166
767
4.95861
822
4.95556
716
4.95252
690
4.94949
679
4.94646
637
4.94344
640
4.94042
625
4.93741
590
4.9344
568
4.9314
506
4.92841
507
4.92542
478
4.92243
end of experiment